[2022-09-05 07:36:39,665] {taskinstance.py:851} INFO - Dependencies all met for <TaskInstance: efishiery_nomor_satu.create_table 2022-09-04T00:00:00+00:00 [queued]>
[2022-09-05 07:36:39,723] {taskinstance.py:851} INFO - Dependencies all met for <TaskInstance: efishiery_nomor_satu.create_table 2022-09-04T00:00:00+00:00 [queued]>
[2022-09-05 07:36:39,724] {taskinstance.py:1042} INFO - 
--------------------------------------------------------------------------------
[2022-09-05 07:36:39,724] {taskinstance.py:1043} INFO - Starting attempt 3 of 3
[2022-09-05 07:36:39,725] {taskinstance.py:1044} INFO - 
--------------------------------------------------------------------------------
[2022-09-05 07:36:39,769] {taskinstance.py:1063} INFO - Executing <Task(PythonOperator): create_table> on 2022-09-04T00:00:00+00:00
[2022-09-05 07:36:39,782] {standard_task_runner.py:52} INFO - Started process 3704 to run task
[2022-09-05 07:36:39,796] {standard_task_runner.py:76} INFO - Running: ['airflow', 'tasks', 'run', 'efishiery_nomor_satu', 'create_table', '2022-09-04T00:00:00+00:00', '--job-id', '151', '--pool', 'default_pool', '--raw', '--subdir', 'DAGS_FOLDER/soal_nomor_satu.py', '--cfg-path', '/tmp/tmp7vvi8pvy', '--error-file', '/tmp/tmpqn7bb3uk']
[2022-09-05 07:36:39,801] {standard_task_runner.py:77} INFO - Job 151: Subtask create_table
[2022-09-05 07:36:39,900] {logging_mixin.py:104} INFO - Running <TaskInstance: efishiery_nomor_satu.create_table 2022-09-04T00:00:00+00:00 [running]> on host 2b8e628fc16c
[2022-09-05 07:36:39,958] {taskinstance.py:1257} INFO - Exporting the following env vars:
AIRFLOW_CTX_DAG_OWNER=farah
AIRFLOW_CTX_DAG_ID=efishiery_nomor_satu
AIRFLOW_CTX_TASK_ID=create_table
AIRFLOW_CTX_EXECUTION_DATE=2022-09-04T00:00:00+00:00
AIRFLOW_CTX_DAG_RUN_ID=scheduled__2022-09-04T00:00:00+00:00
[2022-09-05 07:36:39,971] {base.py:74} INFO - Using connection to: id: efishery. Host: 172.17.0.1, Port: 5432, Schema: efishery, Login: airflow, Password: XXXXXXXX, extra: None
[2022-09-05 07:36:39,984] {taskinstance.py:1455} ERROR - duplicate key value violates unique constraint "products_pkey"
DETAIL:  Key (id)=(477) already exists.
Traceback (most recent call last):
  File "/home/airflow/.local/lib/python3.6/site-packages/airflow/models/taskinstance.py", line 1112, in _run_raw_task
    self._prepare_and_execute_task_with_callbacks(context, task)
  File "/home/airflow/.local/lib/python3.6/site-packages/airflow/models/taskinstance.py", line 1285, in _prepare_and_execute_task_with_callbacks
    result = self._execute_task(context, task_copy)
  File "/home/airflow/.local/lib/python3.6/site-packages/airflow/models/taskinstance.py", line 1315, in _execute_task
    result = task_copy.execute(context=context)
  File "/home/airflow/.local/lib/python3.6/site-packages/airflow/operators/python.py", line 117, in execute
    return_value = self.execute_callable()
  File "/home/airflow/.local/lib/python3.6/site-packages/airflow/operators/python.py", line 128, in execute_callable
    return self.python_callable(*self.op_args, **self.op_kwargs)
  File "/opt/airflow/dags/usecase/soal_nomor_satu.py", line 106, in create_table
    cursor.execute(sql)
psycopg2.errors.UniqueViolation: duplicate key value violates unique constraint "products_pkey"
DETAIL:  Key (id)=(477) already exists.

[2022-09-05 07:36:39,994] {taskinstance.py:1503} INFO - Marking task as FAILED. dag_id=efishiery_nomor_satu, task_id=create_table, execution_date=20220904T000000, start_date=20220905T073639, end_date=20220905T073639
[2022-09-05 07:36:40,128] {local_task_job.py:146} INFO - Task exited with return code 1
[2022-09-05 11:00:15,279] {taskinstance.py:851} INFO - Dependencies all met for <TaskInstance: efishiery_nomor_satu.create_table 2022-09-04T00:00:00+00:00 [queued]>
[2022-09-05 11:00:15,329] {taskinstance.py:851} INFO - Dependencies all met for <TaskInstance: efishiery_nomor_satu.create_table 2022-09-04T00:00:00+00:00 [queued]>
[2022-09-05 11:00:15,329] {taskinstance.py:1042} INFO - 
--------------------------------------------------------------------------------
[2022-09-05 11:00:15,330] {taskinstance.py:1043} INFO - Starting attempt 3 of 4
[2022-09-05 11:00:15,331] {taskinstance.py:1044} INFO - 
--------------------------------------------------------------------------------
[2022-09-05 11:00:15,381] {taskinstance.py:1063} INFO - Executing <Task(PythonOperator): create_table> on 2022-09-04T00:00:00+00:00
[2022-09-05 11:00:15,387] {standard_task_runner.py:52} INFO - Started process 9677 to run task
[2022-09-05 11:00:15,392] {standard_task_runner.py:76} INFO - Running: ['airflow', 'tasks', 'run', 'efishiery_nomor_satu', 'create_table', '2022-09-04T00:00:00+00:00', '--job-id', '155', '--pool', 'default_pool', '--raw', '--subdir', 'DAGS_FOLDER/soal_nomor_satu.py', '--cfg-path', '/tmp/tmplb7tijm_', '--error-file', '/tmp/tmpt_715x7t']
[2022-09-05 11:00:15,396] {standard_task_runner.py:77} INFO - Job 155: Subtask create_table
[2022-09-05 11:00:15,486] {logging_mixin.py:104} INFO - Running <TaskInstance: efishiery_nomor_satu.create_table 2022-09-04T00:00:00+00:00 [running]> on host 2b8e628fc16c
[2022-09-05 11:00:15,556] {taskinstance.py:1257} INFO - Exporting the following env vars:
AIRFLOW_CTX_DAG_OWNER=farah
AIRFLOW_CTX_DAG_ID=efishiery_nomor_satu
AIRFLOW_CTX_TASK_ID=create_table
AIRFLOW_CTX_EXECUTION_DATE=2022-09-04T00:00:00+00:00
AIRFLOW_CTX_DAG_RUN_ID=scheduled__2022-09-04T00:00:00+00:00
[2022-09-05 11:00:15,572] {base.py:74} INFO - Using connection to: id: efishery. Host: 172.17.0.1, Port: 5432, Schema: efishery, Login: airflow, Password: XXXXXXXX, extra: None
[2022-09-05 11:00:15,601] {base.py:74} INFO - Using connection to: id: efishery_dwh. Host: 172.17.0.1, Port: 5432, Schema: efishery_dwh, Login: airflow, Password: XXXXXXXX, extra: None
[2022-09-05 11:00:15,753] {taskinstance.py:1455} ERROR - 'Series' objects are mutable, thus they cannot be hashed
Traceback (most recent call last):
  File "/home/airflow/.local/lib/python3.6/site-packages/airflow/models/taskinstance.py", line 1112, in _run_raw_task
    self._prepare_and_execute_task_with_callbacks(context, task)
  File "/home/airflow/.local/lib/python3.6/site-packages/airflow/models/taskinstance.py", line 1285, in _prepare_and_execute_task_with_callbacks
    result = self._execute_task(context, task_copy)
  File "/home/airflow/.local/lib/python3.6/site-packages/airflow/models/taskinstance.py", line 1315, in _execute_task
    result = task_copy.execute(context=context)
  File "/home/airflow/.local/lib/python3.6/site-packages/airflow/operators/python.py", line 117, in execute
    return_value = self.execute_callable()
  File "/home/airflow/.local/lib/python3.6/site-packages/airflow/operators/python.py", line 128, in execute_callable
    return self.python_callable(*self.op_args, **self.op_kwargs)
  File "/opt/airflow/dags/usecase/soal_nomor_satu.py", line 8, in main
    df = unique_value(df_ops, df_dwh)
  File "/opt/airflow/dags/usecase/soal_nomor_satu.py", line 40, in unique_value
    df = df_ops[df_ops['id'] not in df_dwh['id']]
  File "/home/airflow/.local/lib/python3.6/site-packages/pandas/core/generic.py", line 1721, in __contains__
    return key in self._info_axis
  File "/home/airflow/.local/lib/python3.6/site-packages/pandas/core/indexes/base.py", line 4074, in __contains__
    hash(key)
  File "/home/airflow/.local/lib/python3.6/site-packages/pandas/core/generic.py", line 1669, in __hash__
    f"{repr(type(self).__name__)} objects are mutable, "
TypeError: 'Series' objects are mutable, thus they cannot be hashed
[2022-09-05 11:00:15,768] {taskinstance.py:1503} INFO - Marking task as UP_FOR_RETRY. dag_id=efishiery_nomor_satu, task_id=create_table, execution_date=20220904T000000, start_date=20220905T110015, end_date=20220905T110015
[2022-09-05 11:00:15,886] {local_task_job.py:146} INFO - Task exited with return code 1
[2022-09-05 11:30:05,345] {taskinstance.py:851} INFO - Dependencies all met for <TaskInstance: efishiery_nomor_satu.create_table 2022-09-04T00:00:00+00:00 [queued]>
[2022-09-05 11:30:05,550] {taskinstance.py:851} INFO - Dependencies all met for <TaskInstance: efishiery_nomor_satu.create_table 2022-09-04T00:00:00+00:00 [queued]>
[2022-09-05 11:30:05,552] {taskinstance.py:1042} INFO - 
--------------------------------------------------------------------------------
[2022-09-05 11:30:05,553] {taskinstance.py:1043} INFO - Starting attempt 3 of 4
[2022-09-05 11:30:05,555] {taskinstance.py:1044} INFO - 
--------------------------------------------------------------------------------
[2022-09-05 11:30:05,616] {taskinstance.py:1063} INFO - Executing <Task(PythonOperator): create_table> on 2022-09-04T00:00:00+00:00
[2022-09-05 11:30:05,624] {standard_task_runner.py:52} INFO - Started process 10564 to run task
[2022-09-05 11:30:05,634] {standard_task_runner.py:76} INFO - Running: ['airflow', 'tasks', 'run', 'efishiery_nomor_satu', 'create_table', '2022-09-04T00:00:00+00:00', '--job-id', '163', '--pool', 'default_pool', '--raw', '--subdir', 'DAGS_FOLDER/soal_nomor_satu.py', '--cfg-path', '/tmp/tmphu6hmu9g', '--error-file', '/tmp/tmph4gsnjiw']
[2022-09-05 11:30:05,641] {standard_task_runner.py:77} INFO - Job 163: Subtask create_table
[2022-09-05 11:30:05,733] {logging_mixin.py:104} INFO - Running <TaskInstance: efishiery_nomor_satu.create_table 2022-09-04T00:00:00+00:00 [running]> on host 2b8e628fc16c
[2022-09-05 11:30:05,804] {taskinstance.py:1257} INFO - Exporting the following env vars:
AIRFLOW_CTX_DAG_OWNER=farah
AIRFLOW_CTX_DAG_ID=efishiery_nomor_satu
AIRFLOW_CTX_TASK_ID=create_table
AIRFLOW_CTX_EXECUTION_DATE=2022-09-04T00:00:00+00:00
AIRFLOW_CTX_DAG_RUN_ID=scheduled__2022-09-04T00:00:00+00:00
[2022-09-05 11:30:05,818] {base.py:74} INFO - Using connection to: id: efishery. Host: 172.17.0.1, Port: 5432, Schema: efishery, Login: airflow, Password: XXXXXXXX, extra: None
[2022-09-05 11:30:05,844] {base.py:74} INFO - Using connection to: id: efishery_dwh. Host: 172.17.0.1, Port: 5432, Schema: efishery_dwh, Login: airflow, Password: XXXXXXXX, extra: None
[2022-09-05 11:30:05,870] {base.py:74} INFO - Using connection to: id: efishery_dwh. Host: 172.17.0.1, Port: 5432, Schema: efishery_dwh, Login: airflow, Password: XXXXXXXX, extra: None
[2022-09-05 11:30:05,877] {taskinstance.py:1455} ERROR - syntax error at or near "`"
LINE 1: INSERT INTO dim_customer (`id`,`name`) VALUES (3923,'Ani')
                                  ^
Traceback (most recent call last):
  File "/home/airflow/.local/lib/python3.6/site-packages/airflow/models/taskinstance.py", line 1112, in _run_raw_task
    self._prepare_and_execute_task_with_callbacks(context, task)
  File "/home/airflow/.local/lib/python3.6/site-packages/airflow/models/taskinstance.py", line 1285, in _prepare_and_execute_task_with_callbacks
    result = self._execute_task(context, task_copy)
  File "/home/airflow/.local/lib/python3.6/site-packages/airflow/models/taskinstance.py", line 1315, in _execute_task
    result = task_copy.execute(context=context)
  File "/home/airflow/.local/lib/python3.6/site-packages/airflow/operators/python.py", line 117, in execute
    return_value = self.execute_callable()
  File "/home/airflow/.local/lib/python3.6/site-packages/airflow/operators/python.py", line 128, in execute_callable
    return self.python_callable(*self.op_args, **self.op_kwargs)
  File "/opt/airflow/dags/usecase/soal_nomor_satu.py", line 9, in main
    insert_dwh_table(df)
  File "/opt/airflow/dags/usecase/soal_nomor_satu.py", line 53, in insert_dwh_table
    cursor.execute(sql, tuple(row))
psycopg2.errors.SyntaxError: syntax error at or near "`"
LINE 1: INSERT INTO dim_customer (`id`,`name`) VALUES (3923,'Ani')
                                  ^

[2022-09-05 11:30:05,885] {taskinstance.py:1503} INFO - Marking task as UP_FOR_RETRY. dag_id=efishiery_nomor_satu, task_id=create_table, execution_date=20220904T000000, start_date=20220905T113005, end_date=20220905T113005
[2022-09-05 11:30:05,965] {local_task_job.py:146} INFO - Task exited with return code 1
