[2022-09-05 05:24:46,719] {taskinstance.py:851} INFO - Dependencies all met for <TaskInstance: dag_with_postgres_v1.create_table 2022-09-04T00:00:00+00:00 [queued]>
[2022-09-05 05:24:46,782] {taskinstance.py:851} INFO - Dependencies all met for <TaskInstance: dag_with_postgres_v1.create_table 2022-09-04T00:00:00+00:00 [queued]>
[2022-09-05 05:24:46,783] {taskinstance.py:1042} INFO - 
--------------------------------------------------------------------------------
[2022-09-05 05:24:46,784] {taskinstance.py:1043} INFO - Starting attempt 1 of 2
[2022-09-05 05:24:46,784] {taskinstance.py:1044} INFO - 
--------------------------------------------------------------------------------
[2022-09-05 05:24:46,828] {taskinstance.py:1063} INFO - Executing <Task(PythonOperator): create_table> on 2022-09-04T00:00:00+00:00
[2022-09-05 05:24:46,834] {standard_task_runner.py:52} INFO - Started process 517 to run task
[2022-09-05 05:24:46,843] {standard_task_runner.py:76} INFO - Running: ['airflow', 'tasks', 'run', 'dag_with_postgres_v1', 'create_table', '2022-09-04T00:00:00+00:00', '--job-id', '128', '--pool', 'default_pool', '--raw', '--subdir', 'DAGS_FOLDER/dags_with_postgres.py', '--cfg-path', '/tmp/tmp14ba9ujp', '--error-file', '/tmp/tmpeuyqidbh']
[2022-09-05 05:24:46,849] {standard_task_runner.py:77} INFO - Job 128: Subtask create_table
[2022-09-05 05:24:46,971] {logging_mixin.py:104} INFO - Running <TaskInstance: dag_with_postgres_v1.create_table 2022-09-04T00:00:00+00:00 [running]> on host 2b8e628fc16c
[2022-09-05 05:24:47,116] {taskinstance.py:1257} INFO - Exporting the following env vars:
AIRFLOW_CTX_DAG_OWNER=coder2j
AIRFLOW_CTX_DAG_ID=dag_with_postgres_v1
AIRFLOW_CTX_TASK_ID=create_table
AIRFLOW_CTX_EXECUTION_DATE=2022-09-04T00:00:00+00:00
AIRFLOW_CTX_DAG_RUN_ID=scheduled__2022-09-04T00:00:00+00:00
[2022-09-05 05:24:47,142] {base.py:74} INFO - Using connection to: id: postgres_localhost. Host: host.docker.internal, Port: 5432, Schema: test, Login: airflow, Password: XXXXXXXX, extra: None
[2022-09-05 05:24:47,184] {taskinstance.py:1455} ERROR - could not translate host name "host.docker.internal" to address: Name or service not known
Traceback (most recent call last):
  File "/home/airflow/.local/lib/python3.6/site-packages/airflow/models/taskinstance.py", line 1112, in _run_raw_task
    self._prepare_and_execute_task_with_callbacks(context, task)
  File "/home/airflow/.local/lib/python3.6/site-packages/airflow/models/taskinstance.py", line 1285, in _prepare_and_execute_task_with_callbacks
    result = self._execute_task(context, task_copy)
  File "/home/airflow/.local/lib/python3.6/site-packages/airflow/models/taskinstance.py", line 1315, in _execute_task
    result = task_copy.execute(context=context)
  File "/home/airflow/.local/lib/python3.6/site-packages/airflow/operators/python.py", line 117, in execute
    return_value = self.execute_callable()
  File "/home/airflow/.local/lib/python3.6/site-packages/airflow/operators/python.py", line 128, in execute_callable
    return self.python_callable(*self.op_args, **self.op_kwargs)
  File "/opt/airflow/dags/dags_with_postgres.py", line 21, in postgres_to_s3
    conn = hook.get_conn()
  File "/home/airflow/.local/lib/python3.6/site-packages/airflow/providers/postgres/hooks/postgres.py", line 108, in get_conn
    self.conn = psycopg2.connect(**conn_args)
  File "/home/airflow/.local/lib/python3.6/site-packages/psycopg2/__init__.py", line 127, in connect
    conn = _connect(dsn, connection_factory=connection_factory, **kwasync)
psycopg2.OperationalError: could not translate host name "host.docker.internal" to address: Name or service not known

[2022-09-05 05:24:47,215] {taskinstance.py:1503} INFO - Marking task as UP_FOR_RETRY. dag_id=dag_with_postgres_v1, task_id=create_table, execution_date=20220904T000000, start_date=20220905T052446, end_date=20220905T052447
[2022-09-05 05:24:47,354] {local_task_job.py:146} INFO - Task exited with return code 1
[2022-09-05 05:30:24,897] {taskinstance.py:851} INFO - Dependencies all met for <TaskInstance: dag_with_postgres_v1.create_table 2022-09-04T00:00:00+00:00 [queued]>
[2022-09-05 05:30:24,979] {taskinstance.py:851} INFO - Dependencies all met for <TaskInstance: dag_with_postgres_v1.create_table 2022-09-04T00:00:00+00:00 [queued]>
[2022-09-05 05:30:24,980] {taskinstance.py:1042} INFO - 
--------------------------------------------------------------------------------
[2022-09-05 05:30:24,980] {taskinstance.py:1043} INFO - Starting attempt 1 of 2
[2022-09-05 05:30:24,981] {taskinstance.py:1044} INFO - 
--------------------------------------------------------------------------------
[2022-09-05 05:30:25,078] {taskinstance.py:1063} INFO - Executing <Task(PythonOperator): create_table> on 2022-09-04T00:00:00+00:00
[2022-09-05 05:30:25,083] {standard_task_runner.py:52} INFO - Started process 629 to run task
[2022-09-05 05:30:25,089] {standard_task_runner.py:76} INFO - Running: ['airflow', 'tasks', 'run', 'dag_with_postgres_v1', 'create_table', '2022-09-04T00:00:00+00:00', '--job-id', '129', '--pool', 'default_pool', '--raw', '--subdir', 'DAGS_FOLDER/dags_with_postgres.py', '--cfg-path', '/tmp/tmpltlswhn6', '--error-file', '/tmp/tmpun1bm_bv']
[2022-09-05 05:30:25,095] {standard_task_runner.py:77} INFO - Job 129: Subtask create_table
[2022-09-05 05:30:25,223] {logging_mixin.py:104} INFO - Running <TaskInstance: dag_with_postgres_v1.create_table 2022-09-04T00:00:00+00:00 [running]> on host 2b8e628fc16c
[2022-09-05 05:30:25,324] {taskinstance.py:1257} INFO - Exporting the following env vars:
AIRFLOW_CTX_DAG_OWNER=coder2j
AIRFLOW_CTX_DAG_ID=dag_with_postgres_v1
AIRFLOW_CTX_TASK_ID=create_table
AIRFLOW_CTX_EXECUTION_DATE=2022-09-04T00:00:00+00:00
AIRFLOW_CTX_DAG_RUN_ID=scheduled__2022-09-04T00:00:00+00:00
[2022-09-05 05:30:25,341] {base.py:74} INFO - Using connection to: id: postgres_localhost. Host: host.docker.internal, Port: 5432, Schema: test, Login: airflow, Password: XXXXXXXX, extra: None
[2022-09-05 05:30:25,542] {taskinstance.py:1455} ERROR - could not translate host name "host.docker.internal" to address: Name or service not known
Traceback (most recent call last):
  File "/home/airflow/.local/lib/python3.6/site-packages/airflow/models/taskinstance.py", line 1112, in _run_raw_task
    self._prepare_and_execute_task_with_callbacks(context, task)
  File "/home/airflow/.local/lib/python3.6/site-packages/airflow/models/taskinstance.py", line 1285, in _prepare_and_execute_task_with_callbacks
    result = self._execute_task(context, task_copy)
  File "/home/airflow/.local/lib/python3.6/site-packages/airflow/models/taskinstance.py", line 1315, in _execute_task
    result = task_copy.execute(context=context)
  File "/home/airflow/.local/lib/python3.6/site-packages/airflow/operators/python.py", line 117, in execute
    return_value = self.execute_callable()
  File "/home/airflow/.local/lib/python3.6/site-packages/airflow/operators/python.py", line 128, in execute_callable
    return self.python_callable(*self.op_args, **self.op_kwargs)
  File "/opt/airflow/dags/dags_with_postgres.py", line 21, in postgres_to_s3
    conn = hook.get_conn()
  File "/home/airflow/.local/lib/python3.6/site-packages/airflow/providers/postgres/hooks/postgres.py", line 108, in get_conn
    self.conn = psycopg2.connect(**conn_args)
  File "/home/airflow/.local/lib/python3.6/site-packages/psycopg2/__init__.py", line 127, in connect
    conn = _connect(dsn, connection_factory=connection_factory, **kwasync)
psycopg2.OperationalError: could not translate host name "host.docker.internal" to address: Name or service not known

[2022-09-05 05:30:25,566] {taskinstance.py:1503} INFO - Marking task as UP_FOR_RETRY. dag_id=dag_with_postgres_v1, task_id=create_table, execution_date=20220904T000000, start_date=20220905T053024, end_date=20220905T053025
[2022-09-05 05:30:25,702] {local_task_job.py:146} INFO - Task exited with return code 1
