[2022-09-05 05:34:00,163] {taskinstance.py:851} INFO - Dependencies all met for <TaskInstance: dag_with_postgres_v1.create_table 2022-09-04T00:00:00+00:00 [queued]>
[2022-09-05 05:34:00,213] {taskinstance.py:851} INFO - Dependencies all met for <TaskInstance: dag_with_postgres_v1.create_table 2022-09-04T00:00:00+00:00 [queued]>
[2022-09-05 05:34:00,213] {taskinstance.py:1042} INFO - 
--------------------------------------------------------------------------------
[2022-09-05 05:34:00,214] {taskinstance.py:1043} INFO - Starting attempt 2 of 3
[2022-09-05 05:34:00,215] {taskinstance.py:1044} INFO - 
--------------------------------------------------------------------------------
[2022-09-05 05:34:00,259] {taskinstance.py:1063} INFO - Executing <Task(PythonOperator): create_table> on 2022-09-04T00:00:00+00:00
[2022-09-05 05:34:00,265] {standard_task_runner.py:52} INFO - Started process 701 to run task
[2022-09-05 05:34:00,279] {standard_task_runner.py:76} INFO - Running: ['airflow', 'tasks', 'run', 'dag_with_postgres_v1', 'create_table', '2022-09-04T00:00:00+00:00', '--job-id', '130', '--pool', 'default_pool', '--raw', '--subdir', 'DAGS_FOLDER/dags_with_postgres.py', '--cfg-path', '/tmp/tmpwhocq41o', '--error-file', '/tmp/tmpcslz4m3y']
[2022-09-05 05:34:00,286] {standard_task_runner.py:77} INFO - Job 130: Subtask create_table
[2022-09-05 05:34:00,417] {logging_mixin.py:104} INFO - Running <TaskInstance: dag_with_postgres_v1.create_table 2022-09-04T00:00:00+00:00 [running]> on host 2b8e628fc16c
[2022-09-05 05:34:00,530] {taskinstance.py:1257} INFO - Exporting the following env vars:
AIRFLOW_CTX_DAG_OWNER=coder2j
AIRFLOW_CTX_DAG_ID=dag_with_postgres_v1
AIRFLOW_CTX_TASK_ID=create_table
AIRFLOW_CTX_EXECUTION_DATE=2022-09-04T00:00:00+00:00
AIRFLOW_CTX_DAG_RUN_ID=scheduled__2022-09-04T00:00:00+00:00
[2022-09-05 05:34:00,547] {base.py:74} INFO - Using connection to: id: postgres_localhost. Host: localhost, Port: 5432, Schema: test, Login: airflow, Password: XXXXXXXX, extra: None
[2022-09-05 05:34:00,548] {taskinstance.py:1455} ERROR - could not connect to server: Connection refused
	Is the server running on host "localhost" (127.0.0.1) and accepting
	TCP/IP connections on port 5432?
could not connect to server: Cannot assign requested address
	Is the server running on host "localhost" (::1) and accepting
	TCP/IP connections on port 5432?
Traceback (most recent call last):
  File "/home/airflow/.local/lib/python3.6/site-packages/airflow/models/taskinstance.py", line 1112, in _run_raw_task
    self._prepare_and_execute_task_with_callbacks(context, task)
  File "/home/airflow/.local/lib/python3.6/site-packages/airflow/models/taskinstance.py", line 1285, in _prepare_and_execute_task_with_callbacks
    result = self._execute_task(context, task_copy)
  File "/home/airflow/.local/lib/python3.6/site-packages/airflow/models/taskinstance.py", line 1315, in _execute_task
    result = task_copy.execute(context=context)
  File "/home/airflow/.local/lib/python3.6/site-packages/airflow/operators/python.py", line 117, in execute
    return_value = self.execute_callable()
  File "/home/airflow/.local/lib/python3.6/site-packages/airflow/operators/python.py", line 128, in execute_callable
    return self.python_callable(*self.op_args, **self.op_kwargs)
  File "/opt/airflow/dags/dags_with_postgres.py", line 21, in postgres_to_s3
    conn = hook.get_conn()
  File "/home/airflow/.local/lib/python3.6/site-packages/airflow/providers/postgres/hooks/postgres.py", line 108, in get_conn
    self.conn = psycopg2.connect(**conn_args)
  File "/home/airflow/.local/lib/python3.6/site-packages/psycopg2/__init__.py", line 127, in connect
    conn = _connect(dsn, connection_factory=connection_factory, **kwasync)
psycopg2.OperationalError: could not connect to server: Connection refused
	Is the server running on host "localhost" (127.0.0.1) and accepting
	TCP/IP connections on port 5432?
could not connect to server: Cannot assign requested address
	Is the server running on host "localhost" (::1) and accepting
	TCP/IP connections on port 5432?

[2022-09-05 05:34:00,555] {taskinstance.py:1503} INFO - Marking task as UP_FOR_RETRY. dag_id=dag_with_postgres_v1, task_id=create_table, execution_date=20220904T000000, start_date=20220905T053400, end_date=20220905T053400
[2022-09-05 05:34:00,653] {local_task_job.py:146} INFO - Task exited with return code 1
