[2022-09-05 05:48:03,390] {taskinstance.py:851} INFO - Dependencies all met for <TaskInstance: dag_with_postgres_v1.create_pet_table 2022-09-04T00:00:00+00:00 [queued]>
[2022-09-05 05:48:03,447] {taskinstance.py:851} INFO - Dependencies all met for <TaskInstance: dag_with_postgres_v1.create_pet_table 2022-09-04T00:00:00+00:00 [queued]>
[2022-09-05 05:48:03,448] {taskinstance.py:1042} INFO - 
--------------------------------------------------------------------------------
[2022-09-05 05:48:03,448] {taskinstance.py:1043} INFO - Starting attempt 2 of 3
[2022-09-05 05:48:03,449] {taskinstance.py:1044} INFO - 
--------------------------------------------------------------------------------
[2022-09-05 05:48:03,529] {taskinstance.py:1063} INFO - Executing <Task(PostgresOperator): create_pet_table> on 2022-09-04T00:00:00+00:00
[2022-09-05 05:48:03,534] {standard_task_runner.py:52} INFO - Started process 982 to run task
[2022-09-05 05:48:03,539] {standard_task_runner.py:76} INFO - Running: ['airflow', 'tasks', 'run', 'dag_with_postgres_v1', 'create_pet_table', '2022-09-04T00:00:00+00:00', '--job-id', '133', '--pool', 'default_pool', '--raw', '--subdir', 'DAGS_FOLDER/dags_with_postgres.py', '--cfg-path', '/tmp/tmpz0yg_i51', '--error-file', '/tmp/tmpfip0il10']
[2022-09-05 05:48:03,543] {standard_task_runner.py:77} INFO - Job 133: Subtask create_pet_table
[2022-09-05 05:48:03,633] {logging_mixin.py:104} INFO - Running <TaskInstance: dag_with_postgres_v1.create_pet_table 2022-09-04T00:00:00+00:00 [running]> on host 2b8e628fc16c
[2022-09-05 05:48:03,689] {taskinstance.py:1257} INFO - Exporting the following env vars:
AIRFLOW_CTX_DAG_OWNER=coder2j
AIRFLOW_CTX_DAG_ID=dag_with_postgres_v1
AIRFLOW_CTX_TASK_ID=create_pet_table
AIRFLOW_CTX_EXECUTION_DATE=2022-09-04T00:00:00+00:00
AIRFLOW_CTX_DAG_RUN_ID=scheduled__2022-09-04T00:00:00+00:00
[2022-09-05 05:48:03,690] {postgres.py:69} INFO - Executing: 
            CREATE TABLE IF NOT EXISTS test (
            pet_id SERIAL PRIMARY KEY,
            name VARCHAR NOT NULL,
            pet_type VARCHAR NOT NULL,
            birth_date DATE NOT NULL,
            OWNER VARCHAR NOT NULL);
          
[2022-09-05 05:48:03,701] {base.py:74} INFO - Using connection to: id: postgres_localhost. Host: localhost, Port: 5432, Schema: test, Login: airflow, Password: XXXXXXXX, extra: None
[2022-09-05 05:48:03,702] {taskinstance.py:1455} ERROR - could not connect to server: Connection refused
	Is the server running on host "localhost" (127.0.0.1) and accepting
	TCP/IP connections on port 5432?
could not connect to server: Cannot assign requested address
	Is the server running on host "localhost" (::1) and accepting
	TCP/IP connections on port 5432?
Traceback (most recent call last):
  File "/home/airflow/.local/lib/python3.6/site-packages/airflow/models/taskinstance.py", line 1112, in _run_raw_task
    self._prepare_and_execute_task_with_callbacks(context, task)
  File "/home/airflow/.local/lib/python3.6/site-packages/airflow/models/taskinstance.py", line 1285, in _prepare_and_execute_task_with_callbacks
    result = self._execute_task(context, task_copy)
  File "/home/airflow/.local/lib/python3.6/site-packages/airflow/models/taskinstance.py", line 1315, in _execute_task
    result = task_copy.execute(context=context)
  File "/home/airflow/.local/lib/python3.6/site-packages/airflow/providers/postgres/operators/postgres.py", line 71, in execute
    self.hook.run(self.sql, self.autocommit, parameters=self.parameters)
  File "/home/airflow/.local/lib/python3.6/site-packages/airflow/hooks/dbapi.py", line 173, in run
    with closing(self.get_conn()) as conn:
  File "/home/airflow/.local/lib/python3.6/site-packages/airflow/providers/postgres/hooks/postgres.py", line 108, in get_conn
    self.conn = psycopg2.connect(**conn_args)
  File "/home/airflow/.local/lib/python3.6/site-packages/psycopg2/__init__.py", line 127, in connect
    conn = _connect(dsn, connection_factory=connection_factory, **kwasync)
psycopg2.OperationalError: could not connect to server: Connection refused
	Is the server running on host "localhost" (127.0.0.1) and accepting
	TCP/IP connections on port 5432?
could not connect to server: Cannot assign requested address
	Is the server running on host "localhost" (::1) and accepting
	TCP/IP connections on port 5432?

[2022-09-05 05:48:03,706] {taskinstance.py:1503} INFO - Marking task as UP_FOR_RETRY. dag_id=dag_with_postgres_v1, task_id=create_pet_table, execution_date=20220904T000000, start_date=20220905T054803, end_date=20220905T054803
[2022-09-05 05:48:03,791] {local_task_job.py:146} INFO - Task exited with return code 1
[2022-09-05 06:20:48,726] {taskinstance.py:851} INFO - Dependencies all met for <TaskInstance: dag_with_postgres_v1.create_pet_table 2022-09-04T00:00:00+00:00 [queued]>
[2022-09-05 06:20:48,788] {taskinstance.py:851} INFO - Dependencies all met for <TaskInstance: dag_with_postgres_v1.create_pet_table 2022-09-04T00:00:00+00:00 [queued]>
[2022-09-05 06:20:48,789] {taskinstance.py:1042} INFO - 
--------------------------------------------------------------------------------
[2022-09-05 06:20:48,790] {taskinstance.py:1043} INFO - Starting attempt 2 of 3
[2022-09-05 06:20:48,791] {taskinstance.py:1044} INFO - 
--------------------------------------------------------------------------------
[2022-09-05 06:20:48,826] {taskinstance.py:1063} INFO - Executing <Task(PostgresOperator): create_pet_table> on 2022-09-04T00:00:00+00:00
[2022-09-05 06:20:48,831] {standard_task_runner.py:52} INFO - Started process 1634 to run task
[2022-09-05 06:20:48,836] {standard_task_runner.py:76} INFO - Running: ['airflow', 'tasks', 'run', 'dag_with_postgres_v1', 'create_pet_table', '2022-09-04T00:00:00+00:00', '--job-id', '139', '--pool', 'default_pool', '--raw', '--subdir', 'DAGS_FOLDER/dags_with_postgres.py', '--cfg-path', '/tmp/tmpitgmr3e5', '--error-file', '/tmp/tmp14l5sthr']
[2022-09-05 06:20:48,841] {standard_task_runner.py:77} INFO - Job 139: Subtask create_pet_table
[2022-09-05 06:20:48,920] {logging_mixin.py:104} INFO - Running <TaskInstance: dag_with_postgres_v1.create_pet_table 2022-09-04T00:00:00+00:00 [running]> on host 2b8e628fc16c
[2022-09-05 06:20:48,977] {taskinstance.py:1257} INFO - Exporting the following env vars:
AIRFLOW_CTX_DAG_OWNER=coder2j
AIRFLOW_CTX_DAG_ID=dag_with_postgres_v1
AIRFLOW_CTX_TASK_ID=create_pet_table
AIRFLOW_CTX_EXECUTION_DATE=2022-09-04T00:00:00+00:00
AIRFLOW_CTX_DAG_RUN_ID=scheduled__2022-09-04T00:00:00+00:00
[2022-09-05 06:20:48,978] {postgres.py:69} INFO - Executing: 
            CREATE TABLE IF NOT EXISTS test (
            pet_id SERIAL PRIMARY KEY,
            name VARCHAR NOT NULL,
            pet_type VARCHAR NOT NULL,
            birth_date DATE NOT NULL,
            OWNER VARCHAR NOT NULL);
          
[2022-09-05 06:20:48,991] {base.py:74} INFO - Using connection to: id: postgres_localhost. Host: host.docker.internal:host-gateway, Port: 5432, Schema: test, Login: airflow, Password: XXXXXXXX, extra: None
[2022-09-05 06:20:48,991] {taskinstance.py:1455} ERROR - could not translate host name "host.docker.internal:host-gateway" to address: Name or service not known
Traceback (most recent call last):
  File "/home/airflow/.local/lib/python3.6/site-packages/airflow/models/taskinstance.py", line 1112, in _run_raw_task
    self._prepare_and_execute_task_with_callbacks(context, task)
  File "/home/airflow/.local/lib/python3.6/site-packages/airflow/models/taskinstance.py", line 1285, in _prepare_and_execute_task_with_callbacks
    result = self._execute_task(context, task_copy)
  File "/home/airflow/.local/lib/python3.6/site-packages/airflow/models/taskinstance.py", line 1315, in _execute_task
    result = task_copy.execute(context=context)
  File "/home/airflow/.local/lib/python3.6/site-packages/airflow/providers/postgres/operators/postgres.py", line 71, in execute
    self.hook.run(self.sql, self.autocommit, parameters=self.parameters)
  File "/home/airflow/.local/lib/python3.6/site-packages/airflow/hooks/dbapi.py", line 173, in run
    with closing(self.get_conn()) as conn:
  File "/home/airflow/.local/lib/python3.6/site-packages/airflow/providers/postgres/hooks/postgres.py", line 108, in get_conn
    self.conn = psycopg2.connect(**conn_args)
  File "/home/airflow/.local/lib/python3.6/site-packages/psycopg2/__init__.py", line 127, in connect
    conn = _connect(dsn, connection_factory=connection_factory, **kwasync)
psycopg2.OperationalError: could not translate host name "host.docker.internal:host-gateway" to address: Name or service not known

[2022-09-05 06:20:48,995] {taskinstance.py:1503} INFO - Marking task as UP_FOR_RETRY. dag_id=dag_with_postgres_v1, task_id=create_pet_table, execution_date=20220904T000000, start_date=20220905T062048, end_date=20220905T062048
[2022-09-05 06:20:49,089] {local_task_job.py:146} INFO - Task exited with return code 1
