[2022-09-05 05:54:11,930] {taskinstance.py:851} INFO - Dependencies all met for <TaskInstance: dag_with_postgres_v1.create_pet_table 2022-09-04T00:00:00+00:00 [queued]>
[2022-09-05 05:54:11,989] {taskinstance.py:851} INFO - Dependencies all met for <TaskInstance: dag_with_postgres_v1.create_pet_table 2022-09-04T00:00:00+00:00 [queued]>
[2022-09-05 05:54:11,990] {taskinstance.py:1042} INFO - 
--------------------------------------------------------------------------------
[2022-09-05 05:54:11,990] {taskinstance.py:1043} INFO - Starting attempt 3 of 4
[2022-09-05 05:54:11,991] {taskinstance.py:1044} INFO - 
--------------------------------------------------------------------------------
[2022-09-05 05:54:12,028] {taskinstance.py:1063} INFO - Executing <Task(PostgresOperator): create_pet_table> on 2022-09-04T00:00:00+00:00
[2022-09-05 05:54:12,034] {standard_task_runner.py:52} INFO - Started process 1102 to run task
[2022-09-05 05:54:12,040] {standard_task_runner.py:76} INFO - Running: ['airflow', 'tasks', 'run', 'dag_with_postgres_v1', 'create_pet_table', '2022-09-04T00:00:00+00:00', '--job-id', '134', '--pool', 'default_pool', '--raw', '--subdir', 'DAGS_FOLDER/dags_with_postgres.py', '--cfg-path', '/tmp/tmp03uzyltk', '--error-file', '/tmp/tmpz5q6d0c5']
[2022-09-05 05:54:12,043] {standard_task_runner.py:77} INFO - Job 134: Subtask create_pet_table
[2022-09-05 05:54:12,183] {logging_mixin.py:104} INFO - Running <TaskInstance: dag_with_postgres_v1.create_pet_table 2022-09-04T00:00:00+00:00 [running]> on host 2b8e628fc16c
[2022-09-05 05:54:12,254] {taskinstance.py:1257} INFO - Exporting the following env vars:
AIRFLOW_CTX_DAG_OWNER=coder2j
AIRFLOW_CTX_DAG_ID=dag_with_postgres_v1
AIRFLOW_CTX_TASK_ID=create_pet_table
AIRFLOW_CTX_EXECUTION_DATE=2022-09-04T00:00:00+00:00
AIRFLOW_CTX_DAG_RUN_ID=scheduled__2022-09-04T00:00:00+00:00
[2022-09-05 05:54:12,255] {postgres.py:69} INFO - Executing: 
            CREATE TABLE IF NOT EXISTS test (
            pet_id SERIAL PRIMARY KEY,
            name VARCHAR NOT NULL,
            pet_type VARCHAR NOT NULL,
            birth_date DATE NOT NULL,
            OWNER VARCHAR NOT NULL);
          
[2022-09-05 05:54:12,268] {base.py:74} INFO - Using connection to: id: postgres_localhost. Host: 127.0.0.1, Port: 5432, Schema: test, Login: airflow, Password: XXXXXXXX, extra: None
[2022-09-05 05:54:12,269] {taskinstance.py:1455} ERROR - could not connect to server: Connection refused
	Is the server running on host "127.0.0.1" and accepting
	TCP/IP connections on port 5432?
Traceback (most recent call last):
  File "/home/airflow/.local/lib/python3.6/site-packages/airflow/models/taskinstance.py", line 1112, in _run_raw_task
    self._prepare_and_execute_task_with_callbacks(context, task)
  File "/home/airflow/.local/lib/python3.6/site-packages/airflow/models/taskinstance.py", line 1285, in _prepare_and_execute_task_with_callbacks
    result = self._execute_task(context, task_copy)
  File "/home/airflow/.local/lib/python3.6/site-packages/airflow/models/taskinstance.py", line 1315, in _execute_task
    result = task_copy.execute(context=context)
  File "/home/airflow/.local/lib/python3.6/site-packages/airflow/providers/postgres/operators/postgres.py", line 71, in execute
    self.hook.run(self.sql, self.autocommit, parameters=self.parameters)
  File "/home/airflow/.local/lib/python3.6/site-packages/airflow/hooks/dbapi.py", line 173, in run
    with closing(self.get_conn()) as conn:
  File "/home/airflow/.local/lib/python3.6/site-packages/airflow/providers/postgres/hooks/postgres.py", line 108, in get_conn
    self.conn = psycopg2.connect(**conn_args)
  File "/home/airflow/.local/lib/python3.6/site-packages/psycopg2/__init__.py", line 127, in connect
    conn = _connect(dsn, connection_factory=connection_factory, **kwasync)
psycopg2.OperationalError: could not connect to server: Connection refused
	Is the server running on host "127.0.0.1" and accepting
	TCP/IP connections on port 5432?

[2022-09-05 05:54:12,271] {taskinstance.py:1503} INFO - Marking task as UP_FOR_RETRY. dag_id=dag_with_postgres_v1, task_id=create_pet_table, execution_date=20220904T000000, start_date=20220905T055411, end_date=20220905T055412
[2022-09-05 05:54:12,414] {local_task_job.py:146} INFO - Task exited with return code 1
[2022-09-05 06:22:53,955] {taskinstance.py:851} INFO - Dependencies all met for <TaskInstance: dag_with_postgres_v1.create_pet_table 2022-09-04T00:00:00+00:00 [queued]>
[2022-09-05 06:22:54,006] {taskinstance.py:851} INFO - Dependencies all met for <TaskInstance: dag_with_postgres_v1.create_pet_table 2022-09-04T00:00:00+00:00 [queued]>
[2022-09-05 06:22:54,006] {taskinstance.py:1042} INFO - 
--------------------------------------------------------------------------------
[2022-09-05 06:22:54,007] {taskinstance.py:1043} INFO - Starting attempt 3 of 4
[2022-09-05 06:22:54,007] {taskinstance.py:1044} INFO - 
--------------------------------------------------------------------------------
[2022-09-05 06:22:54,048] {taskinstance.py:1063} INFO - Executing <Task(PostgresOperator): create_pet_table> on 2022-09-04T00:00:00+00:00
[2022-09-05 06:22:54,053] {standard_task_runner.py:52} INFO - Started process 1676 to run task
[2022-09-05 06:22:54,059] {standard_task_runner.py:76} INFO - Running: ['airflow', 'tasks', 'run', 'dag_with_postgres_v1', 'create_pet_table', '2022-09-04T00:00:00+00:00', '--job-id', '140', '--pool', 'default_pool', '--raw', '--subdir', 'DAGS_FOLDER/dags_with_postgres.py', '--cfg-path', '/tmp/tmpy1zpzq5m', '--error-file', '/tmp/tmpm9p9ih9u']
[2022-09-05 06:22:54,065] {standard_task_runner.py:77} INFO - Job 140: Subtask create_pet_table
[2022-09-05 06:22:54,158] {logging_mixin.py:104} INFO - Running <TaskInstance: dag_with_postgres_v1.create_pet_table 2022-09-04T00:00:00+00:00 [running]> on host 2b8e628fc16c
[2022-09-05 06:22:54,230] {taskinstance.py:1257} INFO - Exporting the following env vars:
AIRFLOW_CTX_DAG_OWNER=coder2j
AIRFLOW_CTX_DAG_ID=dag_with_postgres_v1
AIRFLOW_CTX_TASK_ID=create_pet_table
AIRFLOW_CTX_EXECUTION_DATE=2022-09-04T00:00:00+00:00
AIRFLOW_CTX_DAG_RUN_ID=scheduled__2022-09-04T00:00:00+00:00
[2022-09-05 06:22:54,231] {postgres.py:69} INFO - Executing: 
            CREATE TABLE IF NOT EXISTS test (
            pet_id SERIAL PRIMARY KEY,
            name VARCHAR NOT NULL,
            pet_type VARCHAR NOT NULL,
            birth_date DATE NOT NULL,
            OWNER VARCHAR NOT NULL);
          
[2022-09-05 06:22:54,247] {base.py:74} INFO - Using connection to: id: postgres_localhost. Host: 172.17.0.1, Port: 5432, Schema: test, Login: airflow, Password: XXXXXXXX, extra: None
[2022-09-05 06:22:54,255] {dbapi.py:180} INFO - Running statement: 
            CREATE TABLE IF NOT EXISTS test (
            pet_id SERIAL PRIMARY KEY,
            name VARCHAR NOT NULL,
            pet_type VARCHAR NOT NULL,
            birth_date DATE NOT NULL,
            OWNER VARCHAR NOT NULL);
          , parameters: None
[2022-09-05 06:22:54,502] {dbapi.py:186} INFO - Rows affected: -1
[2022-09-05 06:22:54,638] {taskinstance.py:1166} INFO - Marking task as SUCCESS. dag_id=dag_with_postgres_v1, task_id=create_pet_table, execution_date=20220904T000000, start_date=20220905T062253, end_date=20220905T062254
[2022-09-05 06:22:54,721] {taskinstance.py:1220} INFO - 0 downstream tasks scheduled from follow-on schedule check
[2022-09-05 06:22:54,754] {local_task_job.py:146} INFO - Task exited with return code 0
