[2022-09-05 06:04:13,011] {taskinstance.py:851} INFO - Dependencies all met for <TaskInstance: dag_with_postgres_v1.create_pet_table 2022-09-04T00:00:00+00:00 [queued]>
[2022-09-05 06:04:13,055] {taskinstance.py:851} INFO - Dependencies all met for <TaskInstance: dag_with_postgres_v1.create_pet_table 2022-09-04T00:00:00+00:00 [queued]>
[2022-09-05 06:04:13,056] {taskinstance.py:1042} INFO - 
--------------------------------------------------------------------------------
[2022-09-05 06:04:13,056] {taskinstance.py:1043} INFO - Starting attempt 4 of 4
[2022-09-05 06:04:13,057] {taskinstance.py:1044} INFO - 
--------------------------------------------------------------------------------
[2022-09-05 06:04:13,091] {taskinstance.py:1063} INFO - Executing <Task(PostgresOperator): create_pet_table> on 2022-09-04T00:00:00+00:00
[2022-09-05 06:04:13,096] {standard_task_runner.py:52} INFO - Started process 1301 to run task
[2022-09-05 06:04:13,101] {standard_task_runner.py:76} INFO - Running: ['airflow', 'tasks', 'run', 'dag_with_postgres_v1', 'create_pet_table', '2022-09-04T00:00:00+00:00', '--job-id', '135', '--pool', 'default_pool', '--raw', '--subdir', 'DAGS_FOLDER/dags_with_postgres.py', '--cfg-path', '/tmp/tmpkgvd92ix', '--error-file', '/tmp/tmpb9nn4uxf']
[2022-09-05 06:04:13,105] {standard_task_runner.py:77} INFO - Job 135: Subtask create_pet_table
[2022-09-05 06:04:13,198] {logging_mixin.py:104} INFO - Running <TaskInstance: dag_with_postgres_v1.create_pet_table 2022-09-04T00:00:00+00:00 [running]> on host 2b8e628fc16c
[2022-09-05 06:04:13,267] {taskinstance.py:1257} INFO - Exporting the following env vars:
AIRFLOW_CTX_DAG_OWNER=coder2j
AIRFLOW_CTX_DAG_ID=dag_with_postgres_v1
AIRFLOW_CTX_TASK_ID=create_pet_table
AIRFLOW_CTX_EXECUTION_DATE=2022-09-04T00:00:00+00:00
AIRFLOW_CTX_DAG_RUN_ID=scheduled__2022-09-04T00:00:00+00:00
[2022-09-05 06:04:13,268] {postgres.py:69} INFO - Executing: 
            CREATE TABLE IF NOT EXISTS test (
            pet_id SERIAL PRIMARY KEY,
            name VARCHAR NOT NULL,
            pet_type VARCHAR NOT NULL,
            birth_date DATE NOT NULL,
            OWNER VARCHAR NOT NULL);
          
[2022-09-05 06:04:13,280] {base.py:74} INFO - Using connection to: id: postgres_localhost. Host: 127.0.0.1, Port: 5432, Schema: test, Login: airflow, Password: XXXXXXXX, extra: None
[2022-09-05 06:04:13,281] {taskinstance.py:1455} ERROR - could not connect to server: Connection refused
	Is the server running on host "127.0.0.1" and accepting
	TCP/IP connections on port 5432?
Traceback (most recent call last):
  File "/home/airflow/.local/lib/python3.6/site-packages/airflow/models/taskinstance.py", line 1112, in _run_raw_task
    self._prepare_and_execute_task_with_callbacks(context, task)
  File "/home/airflow/.local/lib/python3.6/site-packages/airflow/models/taskinstance.py", line 1285, in _prepare_and_execute_task_with_callbacks
    result = self._execute_task(context, task_copy)
  File "/home/airflow/.local/lib/python3.6/site-packages/airflow/models/taskinstance.py", line 1315, in _execute_task
    result = task_copy.execute(context=context)
  File "/home/airflow/.local/lib/python3.6/site-packages/airflow/providers/postgres/operators/postgres.py", line 71, in execute
    self.hook.run(self.sql, self.autocommit, parameters=self.parameters)
  File "/home/airflow/.local/lib/python3.6/site-packages/airflow/hooks/dbapi.py", line 173, in run
    with closing(self.get_conn()) as conn:
  File "/home/airflow/.local/lib/python3.6/site-packages/airflow/providers/postgres/hooks/postgres.py", line 108, in get_conn
    self.conn = psycopg2.connect(**conn_args)
  File "/home/airflow/.local/lib/python3.6/site-packages/psycopg2/__init__.py", line 127, in connect
    conn = _connect(dsn, connection_factory=connection_factory, **kwasync)
psycopg2.OperationalError: could not connect to server: Connection refused
	Is the server running on host "127.0.0.1" and accepting
	TCP/IP connections on port 5432?

[2022-09-05 06:04:13,285] {taskinstance.py:1503} INFO - Marking task as FAILED. dag_id=dag_with_postgres_v1, task_id=create_pet_table, execution_date=20220904T000000, start_date=20220905T060413, end_date=20220905T060413
[2022-09-05 06:04:13,353] {local_task_job.py:146} INFO - Task exited with return code 1
[2022-09-05 06:27:50,237] {taskinstance.py:851} INFO - Dependencies all met for <TaskInstance: dag_with_postgres_v1.create_pet_table 2022-09-04T00:00:00+00:00 [queued]>
[2022-09-05 06:27:50,296] {taskinstance.py:851} INFO - Dependencies all met for <TaskInstance: dag_with_postgres_v1.create_pet_table 2022-09-04T00:00:00+00:00 [queued]>
[2022-09-05 06:27:50,297] {taskinstance.py:1042} INFO - 
--------------------------------------------------------------------------------
[2022-09-05 06:27:50,297] {taskinstance.py:1043} INFO - Starting attempt 4 of 5
[2022-09-05 06:27:50,298] {taskinstance.py:1044} INFO - 
--------------------------------------------------------------------------------
[2022-09-05 06:27:50,340] {taskinstance.py:1063} INFO - Executing <Task(PostgresOperator): create_pet_table> on 2022-09-04T00:00:00+00:00
[2022-09-05 06:27:50,347] {standard_task_runner.py:52} INFO - Started process 1773 to run task
[2022-09-05 06:27:50,354] {standard_task_runner.py:76} INFO - Running: ['airflow', 'tasks', 'run', 'dag_with_postgres_v1', 'create_pet_table', '2022-09-04T00:00:00+00:00', '--job-id', '141', '--pool', 'default_pool', '--raw', '--subdir', 'DAGS_FOLDER/dags_with_postgres.py', '--cfg-path', '/tmp/tmp_g5pqlzc', '--error-file', '/tmp/tmpzz5hy3xh']
[2022-09-05 06:27:50,359] {standard_task_runner.py:77} INFO - Job 141: Subtask create_pet_table
[2022-09-05 06:27:50,446] {logging_mixin.py:104} INFO - Running <TaskInstance: dag_with_postgres_v1.create_pet_table 2022-09-04T00:00:00+00:00 [running]> on host 2b8e628fc16c
[2022-09-05 06:27:50,500] {taskinstance.py:1257} INFO - Exporting the following env vars:
AIRFLOW_CTX_DAG_OWNER=coder2j
AIRFLOW_CTX_DAG_ID=dag_with_postgres_v1
AIRFLOW_CTX_TASK_ID=create_pet_table
AIRFLOW_CTX_EXECUTION_DATE=2022-09-04T00:00:00+00:00
AIRFLOW_CTX_DAG_RUN_ID=scheduled__2022-09-04T00:00:00+00:00
[2022-09-05 06:27:50,501] {postgres.py:69} INFO - Executing: 
            CREATE TABLE IF NOT EXISTS test (
            pet_id SERIAL PRIMARY KEY,
            name VARCHAR NOT NULL,
            pet_type VARCHAR NOT NULL,
            birth_date DATE NOT NULL,
            OWNER VARCHAR NOT NULL);
          
[2022-09-05 06:27:50,513] {base.py:74} INFO - Using connection to: id: postgres_localhost. Host: 172.17.0.1, Port: 5432, Schema: test, Login: airflow, Password: XXXXXXXX, extra: None
[2022-09-05 06:27:50,518] {dbapi.py:180} INFO - Running statement: 
            CREATE TABLE IF NOT EXISTS test (
            pet_id SERIAL PRIMARY KEY,
            name VARCHAR NOT NULL,
            pet_type VARCHAR NOT NULL,
            birth_date DATE NOT NULL,
            OWNER VARCHAR NOT NULL);
          , parameters: None
[2022-09-05 06:27:50,688] {dbapi.py:186} INFO - Rows affected: -1
[2022-09-05 06:27:50,747] {taskinstance.py:1166} INFO - Marking task as SUCCESS. dag_id=dag_with_postgres_v1, task_id=create_pet_table, execution_date=20220904T000000, start_date=20220905T062750, end_date=20220905T062750
[2022-09-05 06:27:50,830] {taskinstance.py:1220} INFO - 0 downstream tasks scheduled from follow-on schedule check
[2022-09-05 06:27:50,846] {local_task_job.py:146} INFO - Task exited with return code 0
