[2022-09-05 06:05:31,655] {taskinstance.py:851} INFO - Dependencies all met for <TaskInstance: dag_with_postgres_v1.create_pet_table 2022-09-04T00:00:00+00:00 [queued]>
[2022-09-05 06:05:31,709] {taskinstance.py:851} INFO - Dependencies all met for <TaskInstance: dag_with_postgres_v1.create_pet_table 2022-09-04T00:00:00+00:00 [queued]>
[2022-09-05 06:05:31,710] {taskinstance.py:1042} INFO - 
--------------------------------------------------------------------------------
[2022-09-05 06:05:31,711] {taskinstance.py:1043} INFO - Starting attempt 5 of 6
[2022-09-05 06:05:31,711] {taskinstance.py:1044} INFO - 
--------------------------------------------------------------------------------
[2022-09-05 06:05:31,746] {taskinstance.py:1063} INFO - Executing <Task(PostgresOperator): create_pet_table> on 2022-09-04T00:00:00+00:00
[2022-09-05 06:05:31,751] {standard_task_runner.py:52} INFO - Started process 1328 to run task
[2022-09-05 06:05:31,756] {standard_task_runner.py:76} INFO - Running: ['airflow', 'tasks', 'run', 'dag_with_postgres_v1', 'create_pet_table', '2022-09-04T00:00:00+00:00', '--job-id', '136', '--pool', 'default_pool', '--raw', '--subdir', 'DAGS_FOLDER/dags_with_postgres.py', '--cfg-path', '/tmp/tmp5g4e7rs2', '--error-file', '/tmp/tmp7sp267f0']
[2022-09-05 06:05:31,760] {standard_task_runner.py:77} INFO - Job 136: Subtask create_pet_table
[2022-09-05 06:05:31,853] {logging_mixin.py:104} INFO - Running <TaskInstance: dag_with_postgres_v1.create_pet_table 2022-09-04T00:00:00+00:00 [running]> on host 2b8e628fc16c
[2022-09-05 06:05:31,912] {taskinstance.py:1257} INFO - Exporting the following env vars:
AIRFLOW_CTX_DAG_OWNER=coder2j
AIRFLOW_CTX_DAG_ID=dag_with_postgres_v1
AIRFLOW_CTX_TASK_ID=create_pet_table
AIRFLOW_CTX_EXECUTION_DATE=2022-09-04T00:00:00+00:00
AIRFLOW_CTX_DAG_RUN_ID=scheduled__2022-09-04T00:00:00+00:00
[2022-09-05 06:05:31,913] {postgres.py:69} INFO - Executing: 
            CREATE TABLE IF NOT EXISTS test (
            pet_id SERIAL PRIMARY KEY,
            name VARCHAR NOT NULL,
            pet_type VARCHAR NOT NULL,
            birth_date DATE NOT NULL,
            OWNER VARCHAR NOT NULL);
          
[2022-09-05 06:05:31,925] {base.py:74} INFO - Using connection to: id: postgres_localhost. Host: localhost, Port: 5432, Schema: test, Login: airflow, Password: XXXXXXXX, extra: None
[2022-09-05 06:05:31,926] {taskinstance.py:1455} ERROR - could not connect to server: Connection refused
	Is the server running on host "localhost" (127.0.0.1) and accepting
	TCP/IP connections on port 5432?
could not connect to server: Cannot assign requested address
	Is the server running on host "localhost" (::1) and accepting
	TCP/IP connections on port 5432?
Traceback (most recent call last):
  File "/home/airflow/.local/lib/python3.6/site-packages/airflow/models/taskinstance.py", line 1112, in _run_raw_task
    self._prepare_and_execute_task_with_callbacks(context, task)
  File "/home/airflow/.local/lib/python3.6/site-packages/airflow/models/taskinstance.py", line 1285, in _prepare_and_execute_task_with_callbacks
    result = self._execute_task(context, task_copy)
  File "/home/airflow/.local/lib/python3.6/site-packages/airflow/models/taskinstance.py", line 1315, in _execute_task
    result = task_copy.execute(context=context)
  File "/home/airflow/.local/lib/python3.6/site-packages/airflow/providers/postgres/operators/postgres.py", line 71, in execute
    self.hook.run(self.sql, self.autocommit, parameters=self.parameters)
  File "/home/airflow/.local/lib/python3.6/site-packages/airflow/hooks/dbapi.py", line 173, in run
    with closing(self.get_conn()) as conn:
  File "/home/airflow/.local/lib/python3.6/site-packages/airflow/providers/postgres/hooks/postgres.py", line 108, in get_conn
    self.conn = psycopg2.connect(**conn_args)
  File "/home/airflow/.local/lib/python3.6/site-packages/psycopg2/__init__.py", line 127, in connect
    conn = _connect(dsn, connection_factory=connection_factory, **kwasync)
psycopg2.OperationalError: could not connect to server: Connection refused
	Is the server running on host "localhost" (127.0.0.1) and accepting
	TCP/IP connections on port 5432?
could not connect to server: Cannot assign requested address
	Is the server running on host "localhost" (::1) and accepting
	TCP/IP connections on port 5432?

[2022-09-05 06:05:31,929] {taskinstance.py:1503} INFO - Marking task as UP_FOR_RETRY. dag_id=dag_with_postgres_v1, task_id=create_pet_table, execution_date=20220904T000000, start_date=20220905T060531, end_date=20220905T060531
[2022-09-05 06:05:32,008] {local_task_job.py:146} INFO - Task exited with return code 1
